Workbook

Sheet README
A1: Mimas — mechanics workbook
A2: Source of truth for mechanic detail, relations and numbers. Created 2026-09-21 from the design page and the 21 Sep design session with Rohan.
A4: What lives where
A5: docs/design/index.html — the rules in prose, with design and code status per concept. Anchors (#id) are cited here in the 'Design anchor' column.
A6: This workbook — every mechanic as a row, how mechanics relate, the trigger vocabulary, every tunable number and where it is shipped, open questions and the decision log.
A7: MimasClient/Assets/_Game/Data/**/*.json — the shipped values. When a number here and a number there disagree, the JSON is what the game does and this sheet is what it should do; fix one or the other.
A8: studio/pillars.md — outranks all of it.
A10: How to use
A11: 1. Adding a mechanic: add a row on Mechanics with a new M-id, its family, status and anchor. Add its edges on Relations. Add its numbers on Tunables. Add what it leaves open on Open questions.
A12: 2. Deciding something: change the status on Mechanics, log the decision on Decisions with the date, and answer the row on Open questions.
A13: 3. Changing a number: edit the blue cell on Tunables (or the entity sheet), then change the JSON, then note it in Changelog. The 'Shipped value' column is what the JSON says today; 'Target' is what design wants.
A14: 4. Never rename an M-id or T-id; they are referenced across sheets and from documents.
... A33: Status at a glance (live counts from Mechanics)
A34: Design status | B34: Count
A35: decided | B35: =COUNTIF(Mechanics!$D:$D,A35) -> 33
A36: proposed | B36: =COUNTIF(Mechanics!$D:$D,A36) -> 25
A37: open | B37: =COUNTIF(Mechanics!$D:$D,A37) -> 1
A38: superseded | B38: =COUNTIF(Mechanics!$D:$D,A38) -> 0
A40: Code status | B40: Count
A41: implemented | B41: =COUNTIF(Mechanics!$E:$E,A41) -> 18
A42: partial | B42: =COUNTIF(Mechanics!$E:$E,A42) -> 8
A43: not-started | B43: =COUNTIF(Mechanics!$E:$E,A43) -> 32
A44: drift | B44: =COUNTIF(Mechanics!$E:$E,A44) -> 1
A46: Mechanics total | B46: =COUNTA(Mechanics!$A:$A)-1 -> 59
A47: Open questions still open | B47: =COUNTIF('Open questions'!$D:$D,"open") -> 49
A48: Tunables still TBD | B48: =COUNTIF(Tunables!$E:$E,"TBD*") -> 8

Sheet Mechanics
A1: ID | B1: Name | C1: Family | D1: Design status | E1: Code status | F1: Pillars served | G1: Design anchor | H1: Rule (one paragraph) | I1: Hidden-info state | J1: Economy / cost | K1: Counterplay | L1: Decided on | M1: Source | N1: Notes | O1: Depends on (count) | P1: Feeds (count)
A2: M-001 | B2: Session (best of 3 over the ladder) | C2: Loop | D2: decided | E2: drift | F2: 1, 4 | G2: #session | H2: One matchmade encounter: best of 3 rounds on successive ladder maps, a draft between rounds; gear, lineage, boons and reveals carry forward. | I2: Reveals persist for the session. | J2: — | K2: — | L2: 2026-09-16 | M2: design #session | N2: Code has one round (MatchState) and no series wrapper; M3. | O2: =COUNTIF(Relations!$A:$A,A2) -> 3 | P2: =COUNTIF(Relations!$D:$D,A2) -> 0
A3: M-002 | B3: Round | C3: Loop | D3: decided | E3: implemented | F3: 1 | G3: #round | H3: One map, alternating turns, until a hero dies. Health, AP, one-round states and (new) every build reset between rounds. | I3: — | J3: — | K3: — | L3: 2026-09-16 | M3: design #round | N3: Builds vanish at round end (21 Sep). | O3: =COUNTIF(Relations!$A:$A,A3) -> 3 | P3: =COUNTIF(Relations!$D:$D,A3) -> 1
A4: M-003 | B4: Turn and action points | C4: Loop | D4: decided | E4: implemented | F4: 1, 2 | G4: #turns | H4: 3 AP per turn on the unit; every ability has a flat cost; unspent AP is lost; End Turn or the clock passes. | I4: — | J4: AP is the single economy. Building and destroying spend it too (21 Sep). | K4: — | L4: 2026-09-15 | M4: ADR-015/016/018 | N4: AP lives on the unit so summons could have their own; 21 Sep decided structures do not spend AP of their own (M-076). | O4: =COUNTIF(Relations!$A:$A,A4) -> 3 | P4: =COUNTIF(Relations!$D:$D,A4) -> 1
A5: M-004 | B5: Time control and clock | C5: Loop | D5: proposed | E5: partial | F5: 1 | G5: #time-controls | H5: One mode at launch: 30 s per turn, server is timekeeper, lag grace capped. Chess-style banks later. | I5: — | J5: Guaranteed actions resolve before the clock starts the owner's turn (21 Sep, proposed). | K5: — | L5: 2026-09-17 | M5: ADR-027 | O5: =COUNTIF(Relations!$A:$A,A5) -> 1 | P5: =COUNTIF(Relations!$D:$D,A5) -> 1
A6: M-005 | B6: Character select | C6: Loop | D6: decided | E6: not-started | F6: 2 | G6: #character-select | H6: Pick four gear items, then a lineage. Simultaneous, private, timed. | I6: Lineage hidden; gear public. | J6: — | K6: — | L6: 2026-09-16 | M6: design #character-select | O6: =COUNTIF(Relations!$A:$A,A6) -> 0 | P6: =COUNTIF(Relations!$D:$D,A6) -> 0
A7: M-006 | B7: Draft between rounds | C7: Loop | D7: decided | E7: not-started | F7: 4, 7 | G7: #draft | H7: Three boon offers from the lineage pool, keep one; seeded; private. | I7: Pick hidden; opponent sees 'picked'. | J7: — | K7: — | L7: 2026-09-16 | M7: design #draft | O7: =COUNTIF(Relations!$A:$A,A7) -> 0 | P7: =COUNTIF(Relations!$D:$D,A7) -> 1
A8: M-007 | B8: Win conditions | C8: Loop | D8: decided | E8: partial | F8: 1 | G8: #win-conditions | H8: Round: hero at 0 hp. Session: majority of rounds. Resign, forfeit; simultaneous death: active player loses (proposed). | I8: — | J8: — | K8: — | L8: 2026-09-16 | M8: design #win-conditions | N8: Laser ticks and traps make environment damage real; the simultaneous-death rule matters now. | O8: =COUNTIF(Relations!$A:$A,A8) -> 2 | P8: =COUNTIF(Relations!$D:$D,A8) -> 0
A9: M-010 | B9: Hex board, terrain, height | C9: Board | D9: decided | E9: implemented | F9: 2 | G9: #board | H9: Axial hex tiles with terrain, integer height level and optional modifier. Body units: 3 per level, hero body 6, aim 4. | I9: Public. | J9: — | K9: — | L9: 2026-09-16 | M9: ADR-003/013/023 | O9: =COUNTIF(Relations!$A:$A,A9) -> 1 | P9: =COUNTIF(Relations!$D:$D,A9) -> 0
A10: M-011 | B10: Line of sight ray | C10: Board | D10: decided | E10: implemented | F10: 2, 5 | G10: #line-of-sight | H10: Straight ray between aim points over heights in body units; bodies block; supercover on grazes; symmetric. | I10: Public geometry. | J10: — | K10: Cover. | L10: 2026-09-16 | M10: ADR-023 | N10: 21 Sep: the aura (M-060) is cut by this same ray, so one sight rule serves attacks, teleports and vision. | O10: =COUNTIF(Relations!$A:$A,A10) -> 3 | P10: =COUNTIF(Relations!$D:$D,A10) -> 4
A11: M-012 | B11: Props: walls and pillars | C11: Board | D11: decided | E11: implemented | F11: 2 | G11: #props | H11: Neutral public bodies placed by the map. Anything with health can be hit; a wall cannot. Destroyed props vanish. | I11: Public. | J11: — | K11: Shoot a pillar down. | L11: 2026-09-16 | M11: ADR-024 | N11: Structures (M-075) are owned props; the open question q-props-owned is answered by the 21 Sep session. | O11: =COUNTIF(Relations!$A:$A,A11) -> 1 | P11: =COUNTIF(Relations!$D:$D,A11) -> 1
A12: M-013 | B12: Maps and the ladder | C12: Board | D12: decided | E12: implemented | F12: 3, 14 | G12: #maps | H12: Symmetric hex lists with two spawns and a ladder position; validated at boot. | I12: Public. | J12: — | K12: — | L12: 2026-09-16 | M12: ADR-014 | N12: Which ladder position first allows builds and fog is open (OQ-N06). | O12: =COUNTIF(Relations!$A:$A,A12) -> 1 | P12: =COUNTIF(Relations!$D:$D,A12) -> 1
A13: M-014 | B13: Tile effects and pickups | C13: Board | D13: open | E13: not-started | F13: 4 | G13: #tile-effects | H13: Terrain modifiers exist; pickups and hazards are not designed. OnEnter hook is ready (EnteredTiles). | I13: Was proposed 'always public'; overturned 21 Sep: traps are hidden board state. | J13: — | K13: — | M13: design #tile-effects | N13: Traps (M-077) are the first hidden tile effect. | O13: =COUNTIF(Relations!$A:$A,A13) -> 1 | P13: =COUNTIF(Relations!$D:$D,A13) -> 1
A14: M-015 | B14: High ground | C14: Board | D14: decided | E14: implemented | F14: 2 | G14: #board | H14: +2 flat damage when the attacker's tile is higher than the target's, every trajectory. | I14: Public global modifier. | J14: — | K14: — | L14: 2026-09-15 | M14: modifiers/high-ground.json | O14: =COUNTIF(Relations!$A:$A,A14) -> 0 | P14: =COUNTIF(Relations!$D:$D,A14) -> 1
A15: M-020 | B15: Character = gear + lineage + boons | C15: Character | D15: decided | E15: implemented | F15: 2 | G15: #character | H15: No classes. Stats, abilities and modifiers are all derived sums. | I15: — | J15: — | K15: — | L15: 2026-09-16 | M15: design #character | N15: 21 Sep adds three innate actions (M-070) to what every hero has. | O15: =COUNTIF(Relations!$A:$A,A15) -> 4 | P15: =COUNTIF(Relations!$D:$D,A15) -> 0
A16: M-021 | B16: Stats | C16: Character | D16: decided | E16: implemented | F16: 2 | G16: #stats | H16: hp, ap, power.weapon, power.spell, defense.weapon, defense.spell. Integers, additive, no negatives on items. | I16: Public as far as gear explains them. | J16: — | K16: — | L16: 2026-09-16 | M16: ADR-017 | N16: Aura radius is not a stat yet; see OQ-N01. | O16: =COUNTIF(Relations!$A:$A,A16) -> 1 | P16: =COUNTIF(Relations!$D:$D,A16) -> 0
A17: M-022 | B17: Gear: four slots | C17: Character | D17: decided | E17: implemented | F17: 2 | G17: #equipment | H17: Weapon, crown, boots, armour. Mandatory, locked for the session. Items are pure additions. | I17: Identity public; abilities hidden until used. | J17: — | K17: — | L17: 2026-09-16 | M17: design #equipment | O17: =COUNTIF(Relations!$A:$A,A17) -> 1 | P17: =COUNTIF(Relations!$D:$D,A17) -> 1
A18: M-023 | B18: Weapon slot | C18: Character | D18: decided | E18: implemented | F18: 2 | G18: #weapon | H18: Two weapon-lane attacks and Strength. Bow: arc, no sight, 1..5. Gun: direct, sight, 1..7. Blade deferred. | I18: — | J18: — | K18: — | L18: 2026-09-16 | M18: design #weapon | O18: =COUNTIF(Relations!$A:$A,A18) -> 0 | P18: =COUNTIF(Relations!$D:$D,A18) -> 0
A19: M-024 | B19: Crown slot | C19: Character | D19: decided | E19: implemented | F19: 2 | G19: #crown | H19: Two spell-lane attacks and Magic; may carry an element. | I19: — | J19: — | K19: — | L19: 2026-09-16 | M19: design #crown | N19: Whether a spell needs vision is per spell (M-063). | O19: =COUNTIF(Relations!$A:$A,A19) -> 0 | P19: =COUNTIF(Relations!$D:$D,A19) -> 0
A20: M-025 | B20: Boots slot | C20: Character | D20: decided | E20: implemented | F20: 12 | G20: #boots | H20: One extra movement mode (jump, teleport; later fly, dash); walk is innate. | I20: — | J20: — | K20: — | L20: 2026-09-16 | M20: design #boots | O20: =COUNTIF(Relations!$A:$A,A20) -> 0 | P20: =COUNTIF(Relations!$D:$D,A20) -> 0
A21: M-026 | B21: Armour slot | C21: Character | D21: decided | E21: implemented | F21: 2 | G21: #armour | H21: Flat subtractive defence per lane; main source of Health. No ablative pool. | I21: — | J21: — | K21: — | L21: 2026-09-16 | M21: design #armour | O21: =COUNTIF(Relations!$A:$A,A21) -> 0 | P21: =COUNTIF(Relations!$D:$D,A21) -> 0
A22: M-030 | B22: Abilities | C22: Combat | D22: decided | E22: partial | F22: 2 | G22: #abilities | H22: Anything a unit spends AP on: movement or attack (21 Sep adds build and destroy as innate). Flat cost, HUD category, from gear or sigils. | I22: Hidden until first use. | J22: — | K22: — | L22: 2026-09-15 | M22: ADR-012/016 | N22: Enchant overrides do not exist in code. | O22: =COUNTIF(Relations!$A:$A,A22) -> 4 | P22: =COUNTIF(Relations!$D:$D,A22) -> 1
A23: M-031 | B23: Movement kinds | C23: Combat | D23: decided | E23: implemented | F23: 12 | G23: #movement | H23: Walk (path, cost, climb), jump (line, arc clearance), teleport (point, sight), fly (walk with ignoreHeight). Path vs EnteredTiles. | I23: — | J23: — | K23: — | L23: 2026-09-15 | M23: ADR-012 | N23: Laser crossing (M-079) needs Path, not EnteredTiles; see OQ-N03. | O23: =COUNTIF(Relations!$A:$A,A23) -> 2 | P23: =COUNTIF(Relations!$D:$D,A23) -> 2
A24: M-032 | B24: Attacks and range band | C24: Combat | D24: decided | E24: partial | F24: 2 | G24: #attacks | H24: Target one damageable body inside a Euclidean minRange..range circle; lane, base damage, element, tags. Ground targeting refused today. | I24: — | J24: — | K24: — | L24: 2026-09-16 | M24: ADR-017/023 | N24: 21 Sep: blind shots (M-064) make tile targeting legal when the tile is out of vision. | O24: =COUNTIF(Relations!$A:$A,A24) -> 6 | P24: =COUNTIF(Relations!$D:$D,A24) -> 1
A25: M-033 | B25: Trajectories | C25: Combat | D25: decided | E25: implemented | F25: 2 | G25: #trajectories | H25: direct (the sight ray), arc (integer parabola with apex), sky (nothing blocks). Independent of lineOfSight. | I25: — | J25: — | K25: — | L25: 2026-09-16 | M25: ADR-023 | O25: =COUNTIF(Relations!$A:$A,A25) -> 0 | P25: =COUNTIF(Relations!$D:$D,A25) -> 2
A26: M-034 | B26: Damage formula | C26: Combat | D26: decided | E26: partial | F26: 2 | G26: #damage | H26: max(0, base + power.lane − defense.lane + Σ flat modifiers); preview and actual are one function; hidden lines show as '?'. | I26: Hidden modifiers revealed when they change a result. | J26: — | K26: — | L26: 2026-09-15 | M26: ADR-017 | N26: nullify not in code. | O26: =COUNTIF(Relations!$A:$A,A26) -> 2 | P26: =COUNTIF(Relations!$D:$D,A26) -> 1
A27: M-035 | B27: Elements | C27: Combat | D27: decided | E27: not-started | F27: 2 | G27: #elements | H27: A modifier class tag on an attack (fire, frost, …) matched by riders, resistances, immunities. Not a lane. | I27: — | J27: — | K27: — | L27: 2026-09-16 | M27: design #elements | O27: =COUNTIF(Relations!$A:$A,A27) -> 1 | P27: =COUNTIF(Relations!$D:$D,A27) -> 0
A28: M-036 | B28: Modifiers | C28: Combat | D28: decided | E28: partial | F28: 2 | G28: #modifiers | H28: One trigger (dealDamage / takeDamage), a conjunction of conditions, one flat effect. Owned by unit, terrain, hex or rules. | I28: public or hidden until it changes a result. | J28: — | K28: — | L28: 2026-09-15 | M28: ADR-017 | N28: The trigger vocabulary (M-091) generalises this. | O28: =COUNTIF(Relations!$A:$A,A28) -> 1 | P28: =COUNTIF(Relations!$D:$D,A28) -> 2
A29: M-040 | B29: Divine lineage | C29: Divine | D29: decided | E29: not-started | F29: 2, 8 | G29: #lineage | H29: Greek / Norse / Hindu: a starting Blessing and the draft pool. Hidden until a boon of it is revealed. | I29: Hidden. | J29: — | K29: — | L29: 2026-09-16 | M29: design #lineage | N29: 21 Sep: each lineage also has unique buildables (M-073); a seen lineage build reveals the lineage (M-083). | O29: =COUNTIF(Relations!$A:$A,A29) -> 2 | P29: =COUNTIF(Relations!$D:$D,A29) -> 1
A30: M-041 | B30: Boons (umbrella) | C30: Divine | D30: decided | E30: not-started | F30: 4, 7, 8 | G30: #boons | H30: Blessing (passive on character), Enchant (change an item), Sigil (new ability on an item). Drafted, session-long, hidden until observed. | I30: Hidden until observed. | J30: — | K30: — | L30: 2026-09-16 | M30: design #boons | N30: 21 Sep: Enchants and Sigils may also target a buildable (M-082). | O30: =COUNTIF(Relations!$A:$A,A30) -> 4 | P30: =COUNTIF(Relations!$D:$D,A30) -> 2
A31: M-042 | B31: Blessing | C31: Divine | D31: decided | E31: not-started | F31: 8 | G31: #blessing | H31: Passive on the character: stat, modifier, AP. | I31: Hidden until it changes a result. | J31: — | K31: — | L31: 2026-09-16 | M31: design #blessing | N31: May change aura radius (M-060). | O31: =COUNTIF(Relations!$A:$A,A31) -> 1 | P31: =COUNTIF(Relations!$D:$D,A31) -> 1
A32: M-043 | B32: Enchant | C32: Divine | D32: decided | E32: not-started | F32: 8 | G32: #enchant | H32: Changes one equipped item's numbers, adds an element or a modifier. | I32: Revealed when an altered number is observed. | J32: — | K32: — | L32: 2026-09-16 | M32: design #enchant | O32: =COUNTIF(Relations!$A:$A,A32) -> 0 | P32: =COUNTIF(Relations!$D:$D,A32) -> 2
A33: M-044 | B33: Sigil | C33: Divine | D33: decided | E33: not-started | F33: 8 | G33: #sigil | H33: Adds a new active ability to one equipped item. | I33: Revealed on first use. | J33: — | K33: — | L33: 2026-09-16 | M33: design #sigil | O33: =COUNTIF(Relations!$A:$A,A33) -> 0 | P33: =COUNTIF(Relations!$D:$D,A33) -> 2
A34: M-050 | B34: Hidden information and reveal | C34: Information | D34: decided | E34: partial | F34: 3 | G34: #hidden-info | H34: Server holds truth; clients get a PlayerView. Gear, stats, health, position public; abilities, lineage, boons hidden until used; revealed sets persist per session. | I34: The rule itself. | J34: — | K34: — | L34: 2026-09-15 | M34: ADR-010/017/018/026 | N34: 21 Sep: position is no longer always public (fog, M-061); anything that attacks is revealed (M-065). | O34: =COUNTIF(Relations!$A:$A,A34) -> 3 | P34: =COUNTIF(Relations!$D:$D,A34) -> 1
A35: M-051 | B35: Determinism and replays | C35: Information | D35: decided | E35: implemented | F35: 2 | G35: #determinism | H35: Same seed + same commands = same state. No floats, no clock in the log. | I35: — | J35: — | K35: — | L35: 2026-09-15 | M35: ADR-014 | N35: Firing order (M-092) must be a pure function of state. | O35: =COUNTIF(Relations!$A:$A,A35) -> 1 | P35: =COUNTIF(Relations!$D:$D,A35) -> 0
A36: M-052 | B36: Client mirror (PlayerView) | C36: Information | D36: decided | E36: implemented | F36: 3, 5 | G36: #hidden-info | H36: The client's MatchState is rebuilt from its PlayerView; it answers previews and refuses illegal commands with the viewer's knowledge only. | I36: — | J36: — | K36: — | L36: 2026-09-17 | M36: ADR-026 | N36: Fog means the PlayerView omits unseen enemy position and unseen builds. | O36: =COUNTIF(Relations!$A:$A,A36) -> 1 | P36: =COUNTIF(Relations!$D:$D,A36) -> 0
A37: M-053 | B37: Bots | C37: Meta | D37: proposed | E37: partial | F37: — | G37: #bots | H37: RandomBot over legal commands; a greedy bot next. Server-side bot seat. | I37: — | J37: — | K37: — | L37: 2026-09-17 | M37: design #bots | N37: Bots must build, destroy and cope with fog once those exist (OQ-N10). | O37: =COUNTIF(Relations!$A:$A,A37) -> 2 | P37: =COUNTIF(Relations!$D:$D,A37) -> 0
A38: M-060 | B38: Aura (area of influence) | C38: Vision | D38: proposed | E38: not-started | F38: 2, 3 | G38: (new) #aura | H38: A circle of tiles around the hero (Euclidean radius like attack ranges), cut by the sight ray from the hero's aim point. The hero's vision equals its aura. Innate actions (build, destroy) reach only inside it. Blessings and similar can change the radius. Strictly hero-based: builds never extend the aura, only vision. | I38: The aura is public geometry once the hero is seen. | J38: No AP; a property. | K38: Break the ray with bodies; stay outside it. | L38: 2026-09-21 | M38: Rohan, 21 Sep round 1 and 2 | N38: Radius base value TBD (T-060). | O38: =COUNTIF(Relations!$A:$A,A38) -> 5 | P38: =COUNTIF(Relations!$D:$D,A38) -> 3
A39: M-061 | B39: Fog of war | C39: Vision | D39: proposed | E39: not-started | F39: 3 | G39: (new) #fog | H39: A player sees only the tiles inside their vision: the hero's aura plus the vision of every build they own. The enemy hero, enemy builds and anything on unseen tiles are absent from the PlayerView. The map itself (terrain, height, neutral props) stays known. | I39: Position becomes hidden information. | J39: — | K39: Builds as scouts; attack reveal. | L39: 2026-09-21 | M39: Rohan, 21 Sep round 1 | N39: Overrides 'hidden information lives on characters, not the board'. Ghost / last-known position not decided (OQ-N02). Research warned: fog + a 30 s clock is the main frustration risk; playtest it. | O39: =COUNTIF(Relations!$A:$A,A39) -> 2 | P39: =COUNTIF(Relations!$D:$D,A39) -> 6
A40: M-062 | B40: Build vision | C40: Vision | D40: proposed | E40: not-started | F40: 3 | G40: (new) #fog | H40: Every build grants its owner vision in a per-kind radius, same shape rule as the aura (circle cut by the sight ray from the build's aim point). Builds are the scouting layer a one-hero game otherwise lacks. | I40: Public once the build is seen. | J40: Part of the build's cost. | K40: Destroy the build. | L40: 2026-09-21 | M40: Rohan, 21 Sep round 1 | O40: =COUNTIF(Relations!$A:$A,A40) -> 1 | P40: =COUNTIF(Relations!$D:$D,A40) -> 2
...

Sheet Relations
A1: From ID | B1: From name | C1: Relation | D1: To ID | E1: To name | F1: Note
A2: M-001 | B2: Session (best of 3 over the ladder) | C2: is made of | D2: M-002 | E2: Round | F2: best of 3 rounds
A3: M-001 | B3: Session (best of 3 over the ladder) | C3: is made of | D3: M-006 | E3: Draft between rounds | F3: a draft between rounds
A4: M-001 | B4: Session (best of 3 over the ladder) | C4: reads | D4: M-013 | E4: Maps and the ladder | F4: rounds follow ladder positions
A5: M-002 | B5: Round | C5: is made of | D5: M-003 | E5: Turn and action points | F5: alternating turns
A6: M-002 | B6: Round | C6: constrains | D6: M-075 | E6: Structure (owned body) | F6: every build vanishes at round end
A7: M-002 | B7: Round | C7: constrains | D7: M-077 | E7: Trap | F7: every trap vanishes at round end
A8: M-003 | B8: Turn and action points | C8: constrains | D8: M-071 | E8: Build | F8: build spends the hero's AP
A9: M-003 | B9: Turn and action points | C9: constrains | D9: M-072 | E9: Destroy | F9: destroy spends the hero's AP
A10: M-003 | B10: Turn and action points | C10: constrains | D10: M-076 | E10: Structure control | F10: directed structure actions spend hero AP; structures have none
A11: M-004 | B11: Time control and clock | C11: reads | D11: M-090 | E11: Guaranteed action | F11: guaranteed actions resolve before the turn clock starts
A12: M-007 | B12: Win conditions | C12: reads | D12: M-079 | E12: Laser sight | F12: laser ticks are environment damage; simultaneous-death rule applies
... A95: M-075 | B95: Structure (owned body) | C95: answers | D95: M-012 | E95: Props: walls and pillars | F95: the design page's open question on owned props (q-props-owned)
A97: Relation kinds: is made of · produces · reads · constrains · extends · reveals · overrides · conflicts with · answers. Solid arrows on the design page's concept map are 'is made of' / 'produces'; dashed are 'reads' / 'constrains'.

Sheet Triggers
A1: Trigger vocabulary: one closed list shared by modifiers, traps, structures and guaranteed actions (M-091). 'In code' = Mimas.Core today. Adding an entry is a design decision and one handler in Core.
A3: Events
A4: Event | B4: Meaning | C4: First user | D4: Status | E4: Mechanic
A5: onDealDamage | B5: The owner is about to deal damage (attacker side). | C5: modifier | D5: in code | E5: M-036
A6: onTakeDamage | B6: The owner is about to take damage (target side). | C6: modifier | D6: in code | E6: M-036
A7: onEnterTile | B7: A body arrives on the tile (walk step, jump landing, teleport landing). Fires per EnteredTiles. | C7: trap | D7: decided 21 Sep | E7: M-077
A8: onCrossTile | B8: A body passes through the tile during a walk without stopping. Fires per Path. Whether jump/teleport 'cross' is OQ-N03. | C8: laser beam | D8: decided 21 Sep (scope open) | E8: M-079
A9: onOwnerTurnStart | B9: The owner's turn begins, before AP is granted and before the clock starts. Fires in placement order (M-092). | C9: guaranteed action | D9: decided 21 Sep | E9: M-090
A10: onAttack | B10: The owner performs any attacking action (hero attack, structure fire, trap fire). | C10: attack reveal | D10: decided 21 Sep | E10: M-065
A11: onBuilt | B11: A build is placed. Used for the trap visibility check (was the tile in enemy vision?). | C11: trap marker | D11: decided 21 Sep | E11: M-078
A12: onDestroyed | B12: A body with health reaches 0 or is destroyed by its owner. | C12: structure death | D12: decided 21 Sep | E12: M-075
A13: onSeen | B13: A tile enters a viewer's vision. Used to reveal structures and to show markers. | C13: reveal | D13: decided 21 Sep | E13: M-078
A14: onEndTurn | B14: The owner's turn ends. | C14: — | D14: reserved, not used | E14: —
A16: Conditions (all must hold)
A17: Condition | B17: Meaning | C17: Status
A18: damageTypes[] | B18: The attack's lane is one of these. | C18: in code
A19: tags[] | B19: The attack carries one of these tags. | C19: in code
A20: heightAdvantage | B20: Attacker's tile is higher than target's. | C20: in code
A21: elements[] | B21: The attack carries one of these elements. | C21: decided, not in code
A22: itemKinds[] | B22: The attack was granted by an item of this kind. | C22: decided, not in code
A23: actor: enemy | owner | any | B23: Who caused the event relative to the trigger's owner. Traps use 'any' (symmetric). | C23: decided 21 Sep
A24: bodyKind: hero | structure | any | B24: What kind of body caused it. | C24: proposed 21 Sep
A25: inAura | B25: The subject tile is inside the owner hero's aura. | C25: decided 21 Sep (build, destroy, directed actions)
A26: inVision | B26: The subject tile is inside the owner's vision. | C26: decided 21 Sep (needsVision)
A27: direction | B27: The beam direction of a directional structure (0..5). | C27: decided 21 Sep (laser)
A29: Effects
A30: Effect | B30: Meaning | C30: Status
A31: damage (signed flat) | B31: Adds to or subtracts from a damage result. | C31: in code
A32: nullify | B32: Sets the damage total to 0 (immunity). | C32: decided, not in code
A33: stat / abilityOverride / addElement / grantAbility | B33: Boon effects on the character or an item. | C33: decided, not in code
A34: dealDamage(amount, lane, element) | B34: A fresh damage event from a structure, trap or beam through the normal damage formula. | C34: decided 21 Sep
A35: spawnBody(kind, tile, direction, owner) | B35: Places a structure. | C35: decided 21 Sep
A36: placeTrap(kind, tile, owner) | B36: Places a trap under a tile. | C36: decided 21 Sep
A37: removeBody / removeTrap | B37: Destroy or consume. | C37: decided 21 Sep
A38: grantVision(radius) | B38: Adds tiles to the owner's vision from a build. | C38: decided 21 Sep
A39: reveal(what, until) | B39: Reveals an actor to the enemy; 'until' = start of the actor's next turn for attack reveal. | C39: decided 21 Sep
A40: mark(tile) | B40: Places a 'something is set here' marker for the enemy. | C40: decided 21 Sep
A41: buildableOverride(kind, field, amount) | B41: An Enchant on a buildable kind. | C41: decided 21 Sep
A42: grantStructureAction(kind, ability) | B42: A Sigil on a structure kind. | C42: decided 21 Sep

Sheet Buildables
A1: Concept catalogue of buildables (M-073). Names and numbers are placeholders (TBD) unless Rohan named them. Base buildables are public to both players; upgrades from boons are hidden until observed (M-082).
A3: ID | B3: Name | C3: Class | D3: Pool | E3: Control (M-076) | F3: Body? | G3: hp | H3: Body height (units) | I3: Vision radius | J3: Build AP | K3: Cap per owner | L3: Directional? | M3: Trigger | N3: Effect | O3: Reveal rule | P3: Notes
A4: B-001 | B4: Laser sight | C4: structure | D4: common | E4: autonomous | F4: yes | G4: TBD | H4: TBD | I4: TBD | J4: TBD | K4: TBD | L4: yes (6 hex directions) | M4: onCrossTile / onEnterTile (move) + onOwnerTurnStart (standing) | N4: dealDamage to the first body on the beam line | O4: structure: fully once seen; beam drawn on tiles | P4: Named by Rohan. Stops at first body. Owner-safety OQ-N08.
A5: B-002 | B5: Scout | C5: structure | D5: common | E5: autonomous (no action) | F5: yes | G5: TBD | H5: TBD (short: does not block sight) | I5: TBD (larger than others) | J5: TBD | K5: TBD | L5: no | M5: — | N5: grantVision; traps in its vision show as markers | O5: structure: fully once seen | P5: Chosen by Rohan as the trap counter.
A6: B-003 | B6: Trap (placeholder name) | C6: trap | D6: common | E6: n/a | F6: no (under the tile) | G6: n/a | H6: n/a | I6: TBD (0 or small) | J6: TBD | K6: TBD | L6: no | M6: onEnterTile, actor any (symmetric) | N6: dealDamage to the entering body; reveal; consume (OQ-N07) | O6: marker if placed inside enemy vision, else invisible; scout shows marker; full on fire | P6: No duds. Symmetric.
A7: B-004 | B7: Barricade (placeholder) | C7: structure | D7: common | E7: autonomous (no action) | F7: yes | G7: TBD | H7: TBD (tall: blocks sight) | I7: TBD | J7: TBD | K7: TBD | L7: no | M7: — | N7: blocks movement and sight; a body in a beam's way | O7: structure: fully once seen | P7: Not asked; suggested as the cheapest counter to a laser. Confirm or delete.
A8: B-101 | B8: Greek unique (TBD) | C8: TBD | D8: lineage: greek | E8: TBD | F8: TBD | G8: TBD | H8: TBD | I8: TBD | J8: TBD | K8: TBD | L8: TBD | M8: TBD | N8: TBD | O8: reveals the lineage when seen (M-083) | P8: Flavour direction: precision and control.
A9: B-201 | B9: Norse unique (TBD) | C9: TBD | D9: lineage: norse | E9: TBD | F9: TBD | G9: TBD | H9: TBD | I9: TBD | J9: TBD | K9: TBD | L9: TBD | M9: TBD | N9: TBD | O9: reveals the lineage when seen (M-083) | P9: Flavour direction: aggression and endurance.
A10: B-301 | B10: Hindu unique (TBD) | C10: TBD | D10: lineage: hindu | E10: TBD | F10: TBD | G10: TBD | H10: TBD | I10: TBD | J10: TBD | K10: TBD | L10: TBD | M10: TBD | N10: TBD | O10: reveals the lineage when seen (M-083) | P10: Flavour direction: elements and transformation.

Sheet Abilities
A1: Shipped abilities from MimasClient/Assets/_Game/Data/abilities/*.json as of 2026-09-21. Blue = the JSON value. needsVision (M-063) is proposed: every attack must declare it; the column shows the proposed default.
A3: id | B3: Name | C3: Type | D3: Category | E3: Granted by | F3: AP cost | G3: Base damage | H3: Lane | I3: Range | J3: Min range | K3: Trajectory / mode | L3: Move range | M3: Other fields | N3: needsVision (M-063) | O3: Source file | P3: Damage per AP | Q3: Hits to fell a pillar (10 hp, no armour, +Str 3)
A4: move | B4: Move | C4: movement | D4: movement | E4: innate | F4: 1 | K4: walk | L4: 1 | M4: climb 1 | O4: abilities/move.json | P4: =IF(G4="","",G4/F4) | Q4: =IF(G4="","",ROUNDUP(Tunables!$C$27/(G4+IF(H4="weapon",Tunables!$C$5+2,Tunables!$C$6+3)),0))
A5: jump | B5: Jump | C5: movement | D5: movement | E5: leaping-boots | F5: 1 | K5: jump | L5: 2 | M5: jumpHeight 1 | O5: abilities/jump.json | P5: =IF(G5="","",G5/F5) | Q5: =IF(G5="","",ROUNDUP(Tunables!$C$27/(G5+IF(H5="weapon",Tunables!$C$5+2,Tunables!$C$6+3)),0))
A6: teleport | B6: Teleport | C6: movement | D6: movement | E6: blink-boots | F6: 1 | K6: teleport | L6: 3 | M6: requiresLineOfSight true | O6: abilities/teleport.json | P6: =IF(G6="","",G6/F6) | Q6: =IF(G6="","",ROUNDUP(Tunables!$C$27/(G6+IF(H6="weapon",Tunables!$C$5+2,Tunables!$C$6+3)),0))
A7: arrow-shot | B7: Arrow Shot | C7: attack | D7: weapon | E7: longbow | F7: 1 | G7: 3 | H7: weapon | I7: 5 | J7: 1 | K7: arc (apex 3) | M7: lineOfSight false | N7: false (proposed) | O7: abilities/arrow-shot.json | P7: =IF(G7="","",G7/F7) -> 3 | Q7: =IF(G7="","",ROUNDUP(Tunables!$C$27/(G7+IF(H7="weapon",Tunables!$C$5+2,Tunables!$C$6+3)),0)) -> 2
A8: aimed-shot | B8: Aimed Shot | C8: attack | D8: weapon | E8: longbow | F8: 2 | G8: 6 | H8: weapon | I8: 5 | J8: 1 | K8: arc (apex 4) | M8: lineOfSight false | N8: false (proposed) | O8: abilities/aimed-shot.json | P8: =IF(G8="","",G8/F8) -> 3 | Q8: =IF(G8="","",ROUNDUP(Tunables!$C$27/(G8+IF(H8="weapon",Tunables!$C$5+2,Tunables!$C$6+3)),0)) -> 2
A9: quick-shot | B9: Quick Shot | C9: attack | D9: weapon | E9: flintlock | F9: 1 | G9: 2 | H9: weapon | I9: 7 | J9: 1 | K9: direct | M9: lineOfSight true | N9: false (proposed) | O9: abilities/quick-shot.json | P9: =IF(G9="","",G9/F9) -> 2 | Q9: =IF(G9="","",ROUNDUP(Tunables!$C$27/(G9+IF(H9="weapon",Tunables!$C$5+2,Tunables!$C$6+3)),0)) -> 2
A10: heavy-shot | B10: Heavy Shot | C10: attack | D10: weapon | E10: flintlock | F10: 2 | G10: 5 | H10: weapon | I10: 7 | J10: 1 | K10: direct | M10: lineOfSight true | N10: false (proposed) | O10: abilities/heavy-shot.json | P10: =IF(G10="","",G10/F10) -> 2.5 | Q10: =IF(G10="","",ROUNDUP(Tunables!$C$27/(G10+IF(H10="weapon",Tunables!$C$5+2,Tunables!$C$6+3)),0)) -> 2
A11: fire-bolt | B11: Fire Bolt | C11: attack | D11: spell | E11: ember-circlet | F11: 2 | G11: 6 | H11: spell | I11: 3 | J11: 1 | K11: direct | M11: lineOfSight true | N11: TBD per spell | O11: abilities/fire-bolt.json | P11: =IF(G11="","",G11/F11) -> 3 | Q11: =IF(G11="","",ROUNDUP(Tunables!$C$27/(G11+IF(H11="weapon",Tunables!$C$5+2,Tunables!$C$6+3)),0)) -> 1
A12: arcane-spark | B12: Arcane Spark | C12: attack | D12: spell | E12: ember-circlet | F12: 1 | G12: 2 | H12: spell | I12: 2 | J12: 1 | K12: direct | M12: lineOfSight true | N12: TBD per spell | O12: abilities/arcane-spark.json | P12: =IF(G12="","",G12/F12) -> 2 | Q12: =IF(G12="","",ROUNDUP(Tunables!$C$27/(G12+IF(H12="weapon",Tunables!$C$5+2,Tunables!$C$6+3)),0)) -> 2
A13: jab | B13: Jab (blade, deferred) | C13: attack | D13: weapon | E13: (unreferenced) | F13: 1 | G13: 2 | H13: weapon | I13: 1 | J13: 1 | K13: direct | M13: lineOfSight true | N13: false (proposed) | O13: abilities/jab.json | P13: =IF(G13="","",G13/F13) -> 2 | Q13: =IF(G13="","",ROUNDUP(Tunables!$C$27/(G13+IF(H13="weapon",Tunables!$C$5+2,Tunables!$C$6+3)),0)) -> 2
A14: strike | B14: Strike (blade, deferred) | C14: attack | D14: weapon | E14: (unreferenced) | F14: 2 | G14: 5 | H14: weapon | I14: 1 | J14: 1 | K14: direct | M14: lineOfSight true | N14: false (proposed) | O14: abilities/strike.json | P14: =IF(G14="","",G14/F14) -> 2.5 | Q14: =IF(G14="","",ROUNDUP(Tunables!$C$27/(G14+IF(H14="weapon",Tunables!$C$5+2,Tunables!$C$6+3)),0)) -> 2

Sheet Items
A1: Shipped items from MimasClient/Assets/_Game/Data/items/*.json as of 2026-09-21. 21 Sep: items may later list buildables the way they list abilities? No — Rohan chose common + lineage buildables (M-073), so items stay as they are.
A3: id | B3: Name | C3: Slot | D3: Kind | E3: hp | F3: power.weapon | G3: power.spell | H3: defense.weapon | I3: defense.spell | J3: Abilities | K3: Tags | L3: Source file
A4: longbow | B4: Longbow | C4: weapon | D4: bow | E4: 0 | F4: 2 | G4: 0 | H4: 0 | I4: 0 | J4: arrow-shot, aimed-shot | K4: bow, ranged | L4: items/longbow.json
A5: flintlock | B5: Flintlock | C5: weapon | D5: gun | E5: 0 | F5: 2 | G5: 0 | H5: 0 | I5: 0 | J5: quick-shot, heavy-shot | K5: gun, ranged | L5: items/flintlock.json
A6: ember-circlet | B6: Ember Circlet | C6: crown | D6: circlet | E6: 0 | F6: 0 | G6: 3 | H6: 0 | I6: 0 | J6: fire-bolt, arcane-spark | K6: crown | L6: items/ember-circlet.json
A7: leaping-boots | B7: Leaping Boots | C7: boots | D7: leaping | E7: 0 | F7: 0 | G7: 0 | H7: 0 | I7: 0 | J7: jump | K7: boots | L7: items/leaping-boots.json
A8: blink-boots | B8: Blink Boots | C8: boots | D8: blink | E8: 0 | F8: 0 | G8: 0 | H8: 0 | I8: 0 | J8: teleport | K8: boots | L8: items/blink-boots.json
A9: leather-jerkin | B9: Leather Jerkin | C9: armour | D9: leather | E9: 8 | F9: 0 | G9: 0 | H9: 2 | I9: 2 | J9: — | K9: armour | L9: items/leather-jerkin.json
A11: Sample hero (longbow, ember-circlet, leaping-boots, leather-jerkin): derived stats = base (Tunables) + items
A12: hp | B12: =Tunables!$C$4+SUMIF($A$4:$A$9,"longbow",E$4:E$9)+SUMIF($A$4:$A$9,"ember-circlet",E$4:E$9)+SUMIF($A$4:$A$9,"leaping-boots",E$4:E$9)+SUMIF($A$4:$A$9,"leather-jerkin",E$4:E$9) -> 28
A13: Strength | B13: =Tunables!$C$5+SUMIF($A$4:$A$9,"longbow",F$4:F$9)+SUMIF($A$4:$A$9,"ember-circlet",F$4:F$9)+SUMIF($A$4:$A$9,"leaping-boots",F$4:F$9)+SUMIF($A$4:$A$9,"leather-jerkin",F$4:F$9) -> 3
A14: Magic | B14: =Tunables!$C$6+SUMIF($A$4:$A$9,"longbow",G$4:G$9)+SUMIF($A$4:$A$9,"ember-circlet",G$4:G$9)+SUMIF($A$4:$A$9,"leaping-boots",G$4:G$9)+SUMIF($A$4:$A$9,"leather-jerkin",G$4:G$9) -> 4
A15: Armour (weapon / spell) | B15: =Tunables!$C$7+SUMIF($A$4:$A$9,"leather-jerkin",H$4:H$9) -> 2 | C15: =Tunables!$C$8+SUMIF($A$4:$A$9,"leather-jerkin",I$4:I$9) -> 2

Sheet Bodies
A1: Everything that stands on a tile with a height: heroes, neutral props (shipped), owned structures (proposed 21 Sep). Sight and trajectories block on 'Body height'; shots land at 'Aim height'.
A3: id | B3: Name | C3: Class | D3: Owner | E3: Body height (units) | F3: Aim height (units) | G3: hp | H3: defense.weapon | I3: defense.spell | J3: Status | K3: Source
A4: hero | B4: Hero | C4: hero | D4: player | E4: 6 | F4: 4 | G4: 20 + armour | H4: 0 + armour | I4: 0 + armour | J4: shipped | K4: rules.json heights; #character
A5: pillar | B5: Stone Pillar | C5: prop | D5: neutral | E5: 6 | F5: 3 | G5: 10 | H5: 0 | I5: 0 | J5: shipped | K5: props/pillar.json
A6: wall | B6: Wall | C6: prop | D6: neutral | E6: 6 | F6: 3 | G6: — (indestructible) | H6: — | I6: — | J6: shipped | K6: props/wall.json
A7: laser-sight | B7: Laser sight (B-001) | C7: structure | D7: owner | E7: TBD | F7: TBD | G7: TBD | H7: TBD | I7: TBD | J7: proposed | K7: Buildables B-001
A8: scout | B8: Scout (B-002) | C8: structure | D8: owner | E8: TBD (short) | F8: TBD | G8: TBD | H8: TBD | I8: TBD | J8: proposed | K8: Buildables B-002
A9: barricade | B9: Barricade (B-004, unconfirmed) | C9: structure | D9: owner | E9: TBD (tall) | F9: TBD | G9: TBD | H9: TBD | I9: TBD | J9: proposed | K9: Buildables B-004
A11: Blocks a flat shot between two ground heroes? (top of column ≥ aim height, from Tunables)
A12: Hero body on level 0 | B12: =IF(Tunables!$C$10>=Tunables!$C$11,"blocks","does not block") -> blocks
A13: Bare level-1 step | B13: =IF(Tunables!$C$9*1>=Tunables!$C$11,"blocks","does not block") -> does not block
A14: Bare level-2 plateau | B14: =IF(Tunables!$C$9*2>=Tunables!$C$11,"blocks","does not block") -> blocks

Sheet Modifiers
A1: Shipped modifiers from MimasClient/Assets/_Game/Data/modifiers/*.json. stone-skin and ward-of-feathers are the bot's hidden passives (DefaultMatchSettings) used to exercise the reveal path.
A3: id | B3: Name | C3: Trigger | D3: When | E3: effect.damage | F3: Visibility | G3: Attached by | H3: Source file
A4: high-ground | B4: High ground | C4: dealDamage | D4: heightAdvantage | E4: 2 | F4: public | G4: global (rules.globalModifiers) | H4: modifiers/high-ground.json
A5: stone-skin | B5: Stone Skin | C5: takeDamage | D5: damageTypes: weapon | E5: -2 | F5: hidden | G5: unit (bot preset) | H5: modifiers/stone-skin.json
A6: ward-of-feathers | B6: Ward of Feathers | C6: takeDamage | D6: damageTypes: spell | E6: -4 | F6: hidden | G6: unit (bot preset) | H6: modifiers/ward-of-feathers.json

Sheet Maps
A1: Shipped maps and terrains. Which ladder position first brings builds, traps and fog is OQ-N06.
A3: Map | B3: Ladder position | C3: Tiles | D3: Symmetry | E3: Heights | F3: Props | G3: Builds allowed (proposed) | H3: Source file
A4: board-3 | B4: 1 | C4: 37 | D4: rotational-180 | E4: flat; one stone hex at centre | F4: none | G4: none | H4: maps/board-3.json
A5: arena-4 | B5: 3 | C5: 61 | D5: rotational-180 | E5: level-2 plateau (3 hexes), level-1 steps (4) | F5: 4 walls, 4 pillars | G5: none | H5: maps/arena-4.json
A8: Terrains
A9: id | B9: walkable | C9: moveCost | D9: Solid for sight? | E9: Source
A10: grass | B10: yes | C10: 1 | D10: no | E10: terrains.json
A11: stone | B11: no | C11: 0 | D11: yes (unwalkable is solid) | E11: terrains.json

Sheet Tunables
A1: Every rule-level number. 'Shipped' is what the JSON says on 2026-09-21 (blue). 'Target' is what design wants; blank means the same as shipped. Yellow TBD = nobody has picked a value. Row positions of T-001..T-011 and T-027 are referenced by formulas on other sheets: do not move those rows.
A3: ID | B3: Key | C3: Shipped value | D3: Unit | E3: Target value | F3: Mechanic | G3: Source | H3: Note
A4: T-001 | B4: baseStats.hp | C4: 20 | D4: hp | F4: M-021 | G4: rules.json | H4: placeholder per design
A5: T-002 | B5: baseStats.power.weapon | C5: 1 | D5: flat | F5: M-021 | G5: rules.json
A6: T-003 | B6: baseStats.power.spell | C6: 1 | D6: flat | F6: M-021 | G6: rules.json
A7: T-004 | B7: baseStats.defense.weapon | C7: 0 | D7: flat | F7: M-021 | G7: rules.json
A8: T-005 | B8: baseStats.defense.spell | C8: 0 | D8: flat | F8: M-021 | G8: rules.json
A9: T-006 | B9: heights.unitsPerLevel | C9: 3 | D9: body units | F9: M-010 | G9: rules.json | H9: one map level
A10: T-007 | B10: heights.body | C10: 6 | D10: body units | F10: M-010 | G10: rules.json | H10: hero body above tile top
A11: T-008 | B11: heights.aim | C11: 4 | D11: body units | F11: M-011 | G11: rules.json | H11: muzzle and landing height
A12: T-009 | B12: baseStats.ap | C12: 3 | D12: AP / turn | F12: M-003 | G12: rules.json
A13: T-010 | B13: clock.turnMs | C13: 30000 | D13: ms | F13: M-004 | G13: rules.json | H13: one mode at launch
A14: T-011 | B14: clock.lagGraceMs | C14: 1000 | D14: ms | F14: M-004 | G14: rules.json | H14: cap on lag compensation
A15: T-012 | B15: clock.reconnectGraceMs | C15: 60000 | D15: ms | F15: M-001 | G15: rules.json | H15: forfeit after
A16: T-013 | B16: high-ground damage | C16: 2 | D16: flat | F16: M-015 | G16: modifiers/high-ground.json
A17: T-014 | B17: walk range / maxClimb | C17: 1 / 1 | D17: hex / level | F17: M-031 | G17: abilities/move.json
A18: T-015 | B18: jump range / jumpHeight | C18: 2 / 1 | D18: hex / level | F18: M-031 | G18: abilities/jump.json
A19: T-016 | B19: teleport range | C19: 3 | D19: hex | F19: M-031 | G19: abilities/teleport.json | H19: needs sight
A20: T-017 | B20: bow range | C20: 1..5 | D20: circle | F20: M-023 | G20: abilities/arrow-shot.json
A21: T-018 | B21: gun range | C21: 1..7 | D21: circle | F21: M-023 | G21: abilities/quick-shot.json
A22: T-019 | B22: session length | C22: best of 3 | D22: rounds | F22: M-001 | G22: #session | H22: not in code
A23: T-020 | B23: character select timer | C23: 60 | D23: s | F23: M-005 | G23: #character-select (proposed) | H23: not in code
A24: T-021 | B24: draft timer | C24: 20 | D24: s | F24: M-006 | G24: #draft (proposed) | H24: not in code
A25: T-022 | B25: draft offers / keep | C25: 3 / 1 | D25: boons | F25: M-006 | G25: #draft
A26: T-023 | B26: time controls (bullet / blitz / rapid) | C26: 60+0 / 180+2 / 600+0 | D26: s bank + s increment | F26: M-004 | G26: timecontrols.json | H26: loaded, unused
A27: T-027 | B27: pillar hp | C27: 10 | D27: hp | F27: M-012 | G27: props/pillar.json | H27: about one turn of damage
A28: T-028 | B28: pillar / wall body height | C28: 6 | D28: body units | F28: M-012 | G28: props/*.json
A29: T-029 | B29: pillar / wall aim height | C29: 3 | D29: body units | F29: M-012 | G29: props/*.json
A30: T-060 | B30: aura radius (base) | C30: TBD | D30: circle radius | E30: TBD | F30: M-060 | G30: (new) | H30: Rohan: not a number to decide today. Somewhere between bow range and gun range is the obvious bracket.
A31: T-061 | B31: build range | C31: same as aura | D31: circle | F31: M-071 | G31: (new) | H31: decided: inside the aura
A32: T-062 | B32: destroy range | C32: same as aura | D32: circle | F32: M-072 | G32: (new) | H32: decided: inside the aura
A33: T-063 | B33: attack reveal duration | C33: until start of attacker's next turn | D33: turns | F33: M-065 | G33: (new) | H33: decided 21 Sep
A34: T-071 | B34: build AP cost per kind | C34: TBD | D34: AP | E34: TBD | F34: M-071 | G34: (new) | H34: per buildable; see Buildables
A35: T-072 | B35: destroy AP cost | C35: TBD | D35: AP | E35: TBD | F35: M-072 | G35: (new)
A36: T-074 | B36: build cap per kind | C36: TBD | D36: count | E36: TBD | F36: M-074 | G36: (new) | H36: per buildable; see Buildables
A37: T-075 | B37: structure hp / body / aim / vision per kind | C37: TBD | D37: various | E37: TBD | F37: M-075 | G37: (new) | H37: see Buildables
A38: T-079 | B38: laser damage (move-through / standing tick) | C38: TBD | D38: flat, lane TBD | E38: TBD | F38: M-079 | G38: (new) | H38: lane and element not decided (OQ-N11)
A39: T-077 | B39: trap damage | C39: TBD | D39: flat, lane TBD | E39: TBD | F39: M-077 | G39: (new) | H39: lane and element not decided (OQ-N11)
A40: T-080 | B40: scout vision radius | C40: TBD | D40: circle radius | E40: TBD | F40: M-080 | G40: (new)
A41: T-090 | B41: guaranteed-action order | C41: placement order | D41: rule | F41: M-092 | G41: (new) | H41: decided 21 Sep
...

Sheet Open questions
A1: ID | B1: Area | C1: Question | D1: Status | E1: Answer / proposal | F1: Answered on | G1: Source | H1: Owner
A2: q-session-length | B2: Loop | C2: Best of 3 vs best of 5 as the default, and whether the count depends on the time control. | D2: open | G2: design page | H2: Rohan
A3: q-session-map-order | B3: Loop | C3: Ladder strictly ordered, or a pool per position? | D3: open | G3: design page | H3: Rohan
A4: q-round-first | B4: Loop | C4: First mover: coin flip then loser-first, or alternate? | D4: open | G4: design page | H4: Rohan
A5: q-round-clock | B5: Loop | C5: Clock per round or per session? | D5: open | G5: design page | H5: Rohan
A6: q-round-flag | B6: Loop | C6: Flag fall = lose round or lose session? | D6: open | G6: design page | H6: Rohan
A7: q-select-catalogue | B7: Loop | C7: Whole catalogue always available, or unlocks / ban-pick? | D7: open | G7: design page | H7: Rohan
A8: q-select-presets | B8: Loop | C8: Presets per account or per browser? | D8: open | G8: design page | H8: Rohan
A9: q-draft-comeback | B9: Loop | C9: Does the round loser get a better offer? | D9: open | G9: design page | H9: Rohan
A10: q-draft-tiers | B10: Loop | C10: Boon tiers / rarity by round? | D10: open | G10: design page | H10: Rohan
A11: q-draft-reroll | B11: Loop | C11: Is there a reroll? | D11: open | G11: design page | H11: Rohan
A12: q-win-draw | B12: Loop | C12: Confirm simultaneous death = active player loses, or allow a draw. | D12: open | G12: design page | H12: Rohan
A13: q-props-owned | B13: Board | C13: Owned props: shield generators, traps, summons a player places. Needs an owner, a spawn action and a reveal rule. | D13: answered | E13: Yes: structures (M-075) and traps (M-077), placed by the innate Build action (M-071), revealed per M-075 / M-078. | F13: 2026-09-21 | G13: design page | H13: Rohan
A14: q-props-rubble | B14: Board | C14: Does a destroyed pillar leave rubble? | D14: open | E14: Proposed: it vanishes. | G14: design page | H14: Rohan
A15: q-maps-count | B15: Board | C15: Maps per ladder position; do players see the next map before drafting? | D15: open | G15: design page | H15: Rohan
A16: q-tiles-pickups | B16: Board | C16: What can a pickup be, does it respawn? | D16: open | G16: design page | H16: Rohan
A17: q-tiles-hazards | B17: Board | C17: Hazards: damage on enter, per turn, knockback into holes? | D17: open | E17: Partly: traps damage on enter (M-077); laser damages on cross and per owner turn (M-079). | G17: design page | H17: Rohan
A18: q-tiles-visibility | B18: Board | C18: Are tile effects always public? | D18: answered | E18: No. Traps are hidden by the placement rule (M-078); fog hides everything on unseen tiles (M-061). | F18: 2026-09-21 | G18: design page | H18: Rohan
A19: q-stats-negative | B19: Character | C19: Can boons lower an enemy's stats? | D19: open | G19: design page | H19: Rohan
A20: q-gear-more | B20: Character | C20: Catalogue growth and unlocks after launch. | D20: open | G20: design page | H20: Rohan
A21: q-weapon-ammo | B21: Character | C21: Ammo / reload, or AP only? | D21: open | E21: Proposed: AP only. | G21: design page | H21: Rohan
A22: q-weapon-blade | B22: Character | C22: When does blade join, with what identity? | D22: open | G22: design page | H22: Rohan
A23: q-crown-utility | B23: Character | C23: Non-damage spells (heal, shield, slow)? | D23: open | E23: Proposed: not at launch. | G23: design page | H23: Rohan
A24: q-attacks-multi | B24: Combat | C24: Multi-hit and area attacks: repeated single resolution or shapes? | D24: open | E24: Proposed: hits: N first. | G24: design page | H24: Rohan
A25: q-trajectory-enchant | B25: Combat | C25: Which Enchant first swaps a trajectory; does it change lineOfSight? | D25: open | G25: design page | H25: Rohan
A26: q-elements-list | B26: Combat | C26: Launch element list. | D26: open | E26: Proposed: fire, frost, lightning. | G26: design page | H26: Rohan
A27: q-elements-status | B27: Combat | C27: Do elements apply statuses? | D27: open | E27: Not at launch. | G27: design page | H27: Rohan
A28: q-lineage-starting | B28: Divine | C28: Starting Blessing per lineage. | D28: open | G28: design page | H28: Rohan
A29: q-lineage-mirror | B29: Divine | C29: Mirror matches: any special rule? | D29: open | E29: Proposed: fine. | G29: design page | H29: Rohan
A30: q-lineage-names | B30: Divine | C30: Naming style for boons. | D30: open | G30: design page | H30: Rohan
A31: q-boons-cap | B31: Divine | C31: Cap on boons per session? | D31: open | G31: design page | H31: Rohan
A32: q-boons-exclusive | B32: Divine | C32: Exclusivity groups? | D32: open | E32: Proposed: yes. | G32: design page | H32: Rohan
A33: q-hidden-enchant-obs | B33: Information | C33: Precise definition of 'observed number' for Enchant reveal. | D33: open | G33: design page | H33: Rohan
A34: q-online-rating | B34: Meta | C34: Confirm Glicko-2 and per-time-control pools. | D34: open | G34: design page | H34: Rohan
A35: q-online-room-loadout | B35: Meta | C35: Should a room show the other seat's preset before the match? | D35: open | G35: design page | H35: Rohan
A36: q-bots-draft | B36: Meta | C36: Bots must pick gear, lineage and drafts. | D36: open | G36: design page | H36: builder
A37: q-pres-select | B37: Presentation | C37: Character select and draft screens not mocked. | D37: open | G37: design page | H37: builder
A38: OQ-N01 | B38: Vision | C38: Is the aura radius a seventh stat (so Blessings change it through the stat effect) or its own field on the character? | D38: open | E38: Proposed: a stat, 'aura', so the existing stat vocabulary carries it. | G38: 21 Sep session | H38: Rohan
A39: OQ-N02 | B39: Vision | C39: When the enemy hero leaves your vision, does a ghost stay at its last known position, and can you blind-shot the ghost? | D39: open | G39: 21 Sep session | H39: Rohan
A40: OQ-N03 | B40: Build | C40: Does a jump or teleport that passes over a laser beam 'cross' it? Movement enters only its destination today (EnteredTiles); crossing would need Path. | D40: open | E40: Proposed: walking crosses; jump and teleport do not (they leave the ground), but landing on the beam counts as entering. | G40: 21 Sep session | H40: Rohan
...

Sheet Decisions
A1: ID | B1: Date | C1: Question | D1: Options offered | E1: Choice | F1: Mechanics | G1: Notes / Rohan's words
A2: D-2026-09-21-01 | B2: 2026-09-21 | C2: Who drives a built thing once it is on the board? | D2: Autonomous only · Hero-directed · Own AP budget · Per-structure data | E2: Per-structure data | F2: M-076 | G2: Some structures fire by themselves (guaranteed actions), some are used with hero AP. Decided in data per kind.
A3: D-2026-09-21-02 | B3: 2026-09-21 | C3: Where does the ability to build come from? | D3: Sigils and gear · A fifth gear slot · Map pickups · Innate to every hero | E3: Innate to every hero | F3: M-070 | G3: Rohan: 'we have 3 innate actions, move, build, destroy (your own build); and each of these will have a range.'
A4: D-2026-09-21-03 | B4: 2026-09-21 | C4: What does 'area of influence' mean on the board? | D4: Reach, no fog · Fog of war · Reach plus soft fog · Contested territory | E4: Fog of war, aura = vision (Rohan's own words) | F4: M-060, M-061, M-062 | G4: Rohan: 'area of influence is where the hero can take innate actions. and fog of war will be the vision to which the hero can see. every player build also gives vision, which area of influence is strictly based on hero… for the hero, their vision will always be equal to their area of influence, lets call it aura. aura can be effected by blessings and such'
A5: D-2026-09-21-04 | B5: 2026-09-21 | C5: When a trap is set on a tile, what does the opponent see? | D5: Marker, not content · Count, not position · Invisible, public pool · Fully invisible | E5: Marker if placed in enemy vision, else invisible (Rohan's own words) | F5: M-078 | G5: Rohan: 'if a trap is placed when the enemy could see it being placed, then we will go with a Marker. but if it is placed where enemy had no vision, then it will be fully invisible.'
A6: D-2026-09-21-05 | B6: 2026-09-21 | C6: Vision is asymmetric. What can you attack? | D6: Only what you see · Range decides, vision only shows · Vision plus memory · Vision for direct, not arcs | E6: Range decides for weapons; a needsVision flag per attack (Rohan's own words) | F6: M-063, M-064 | G6: Rohan: 'for weapon attacks, range decides; so firing blind shots and getting a hit becomes a possibility. for spells it will depend, so we will have another flag of needs vision or not. also having this flag for weapon attacks would be good too, might be useful in future idea'
A7: D-2026-09-21-06 | B7: 2026-09-21 | C7: How is the aura shaped and what stops it? | D7: Circle cut by the sight ray · Plain circle · Circle cut by unwalkable terrain only · Hex distance ring | E7: Circle, cut by the sight ray | F7: M-060 | G7: One sight rule for attacks, teleports and vision.
A8: D-2026-09-21-07 | B8: 2026-09-21 | C8: What decides a hero's buildable catalogue? | D8: Gear carries builds · One universal catalogue · Lineage decides · Universal base plus boons | E8: Common buildables plus lineage-unique (Rohan's own words) | F8: M-073 | G8: Rohan: 'some common buildables + lineage unique. also all the base things should be known to both players easily, its any kind of upgrades that we want to keep hidden until revealed'
A9: D-2026-09-21-08 | B9: 2026-09-21 | C9: What does the enemy learn on seeing a tile you built on? | D9: Structures fully, traps as markers · Everything as markers · Everything fully · Structures fully, traps invisible | E9: Structures fully, traps as markers; plus: anything that attacks is revealed (Rohan's own words) | F9: M-075, M-078, M-065 | G9: Rohan: 'go with point 1. also i want to make it so that whenever anything does an attacking action, then they are revealed to the enemy'
A10: D-2026-09-21-09 | B10: 2026-09-21 | C10: When do guaranteed actions fire, in what order? | D10: Owner's turn start, placement order · Owner picks order · All at once · End of owner's turn | E10: Owner's turn start, placement order | F10: M-090, M-092 | G10: Into the Breach / Hearthstone model. Order shown on the board.
A11: D-2026-09-21-10 | B11: 2026-09-21 | C11: What does the laser beam do? | D11: Hits first body at fire time · Hits every body · Zone, not a shot · Marks, does not damage | E11: Zone, not a shot | F11: M-079 | G11: Damages on entering or crossing during a move.
A12: D-2026-09-21-11 | B12: 2026-09-21 | C12: What can trigger a trap? | D12: Enemy enters · Enemy ends turn on/adjacent · Enemy attacks from/into · Owner's turn start (multi-select) | E12: Enemy enters the tile (only) | F12: M-077 | G12: One trigger in the vocabulary for now.
... A16: D-2026-09-21-15 | B16: 2026-09-21 | C16: Laser edges: standing on the line at turn start; does the beam stop at the first body? | D16: Ticks, stops at first body · Ticks, passes through · Move-only, stops · Move-only, passes | E16: Ticks at turn start, stops at first body | F16: M-079 | G16: Bodies are the counterplay.
A17: D-2026-09-21-16 | B17: 2026-09-21 | C17: How does a blind shot target; how long does attacking reveal you? | D17: Tile; until your next turn · Tile; momentary · Tile; rest of round · No tile targeting | E17: Target a tile; revealed until the start of your next turn | F17: M-064, M-065
A18: D-2026-09-21-17 | B18: 2026-09-21 | C18: What is Destroy for, and where must the build be? | D18: Frees cap and tile, AP, inside aura · Free, anywhere · Detonate · Also disarms enemy builds | E18: Frees cap and tile, costs AP, inside aura | F18: M-072 | G18: Same aura rule for hero-directed structure actions.
A19: D-2026-09-21-18 | B19: 2026-09-21 | C19: How does a player deal with a suspected enemy trap? | D19: Walk into it · Blind-shot the tile · Scout build · Aura reveals traps (multi-select) | E19: Blind-shot the tile; Scout build | F19: M-080, M-081 | G19: The aura alone does NOT reveal traps.
A20: D-2026-09-21-19 | B20: 2026-09-21 | C20: How do boons touch builds? | D20: Enchants and Sigils target buildables · Blessings only · Lineage builds only · New boon kind | E20: Enchants and Sigils target buildables too | F20: M-082 | G20: Hidden until observed, like gear.
A21: D-2026-09-21-21 | B21: 2026-09-21 | C21: Does the laser hurt its own builder? | D21: (asked in the wrap-up, no options) | E21: Yes, the laser can hurt its own builder as well (Rohan's own words) | F21: M-079 | G21: Same symmetry as traps.
A22: D-2026-09-21-20 | B22: 2026-09-21 | C22: How do today's concepts reach the guarded design page? | D22: Brief plus patch · Let me edit it now · Spreadsheet and brief only | E22: Spreadsheet and brief only | F22: — | G22: The design page stays untouched until these are picked up for implementation. This workbook and docs/design/2026-09-21-board-mechanics.md are the record.

Sheet Changelog
A1: Date | B1: Who | C1: What
A2: 2026-09-21 | B2: Claude (design session with Rohan) | C2: Workbook created. Existing mechanics M-001..M-053 transcribed from docs/design/index.html and the shipped JSON. New mechanics M-060..M-092, buildables B-001..B-301, tunables T-060..T-090, open questions OQ-N01..N15 and decisions D-2026-09-21-01..20 from the session.
A3: 2026-09-21 | B3: Claude (wrap-up) | C3: OQ-N08 answered (the laser is symmetric), D-2026-09-21-21 logged, OQ-N16 (auto end turn) added from Rohan's playtest notes.
